Workbook

Sheet Sheet1
G1: =SUM(G3:G56) -> 10575.5 | M1: =SUM(M3:M56) -> 8346.9 | S1: =SUM(S9:S56) -> 38115.5 | X1: =SUM(X4:X57) -> 9515.9 | Z1: =SUM(G1:X1)*7.44 -> 495160.27
A2: Date | B2: Dunkin Blast | F2: Total | G2: Savings | H2: CLC Blast | L2: Total | M2: Savings | N2: BMC | R2: Total | S2: Savings | T2: Deep-1 | U2: deep-2 | V2: rack | W2: Deep-total | X2: Savings | Z2: Value in INR
A3: 46026 | B3: 367509.2 | C3: =B4-B3 -> 586.6 | D3: 464009.3 | E3: =D4-D3 -> 552.4 | F3: =C3+E3 -> 1139 | G3: =1250-F3 -> 111 | H3: 15932.1 | I3: =H4-H3 -> 366.2 | J3: 610143.6 | K3: =J4-J3 -> 1220.1 | L3: =I3+K3 -> 1586.3 | M3: =1450-L3 -> -136.3 | T3: 332392.6 | U3: 224593.7 | V3: 1295390
A4: 46057 | B4: 368095.8 | C4: =B5-B4 -> 590.4 | D4: 464561.7 | E4: =D5-D4 -> 720.2 | F4: =C4+E4 -> 1310.6 | G4: =1250-F4 -> -60.6 | H4: 16298.3 | I4: =H5-H4 -> 352.9 | J4: 611363.7 | K4: =J5-J4 -> 1098.5 | L4: =I4+K4 -> 1451.4 | M4: =1450-L4 -> -1.4 | T4: 332772.3 | U4: 224826.3 | V4: 1296783 | W4: =(T4-T3)+(U4-U3)+(V4-V3) -> 2005.3 | X4: =2200-W4 -> 194.7
A5: 46085 | B5: 368686.2 | C5: =B6-B5 -> 592.9 | D5: 465281.9 | E5: =D6-D5 -> 759.5 | F5: =C5+E5 -> 1352.4 | G5: =1250-F5 -> -102.4 | H5: 16651.2 | I5: =H6-H5 -> 343.3 | J5: 612462.2 | K5: =J6-J5 -> 777.2 | L5: =I5+K5 -> 1120.5 | M5: =1450-L5 -> 329.5 | T5: 333149.5 | U5: 225057.7 | V5: 1298175 | W5: =(T5-T4)+(U5-U4)+(V5-V4) -> 2000.6 | X5: =2200-W5 -> 199.4
A6: 46116 | B6: 369279.1 | C6: =B7-B6 -> 593.6 | D6: 466041.4 | E6: =D7-D6 -> 592.6 | F6: =C6+E6 -> 1186.2 | G6: =1250-F6 -> 63.8 | H6: 16994.5 | I6: =H7-H6 -> 227.7 | J6: 613239.4 | K6: =J7-J6 -> 553.1 | L6: =I6+K6 -> 780.8 | M6: =1450-L6 -> 669.2 | T6: 333528 | U6: 225289.9 | V6: 1299578 | W6: =(T6-T5)+(U6-U5)+(V6-V5) -> 2013.7 | X6: =2200-W6 -> 186.3
A7: 46146 | B7: 369872.7 | C7: =B8-B7 -> 592.6 | D7: 466634 | E7: =D8-D7 -> 684.7 | F7: =C7+E7 -> 1277.3 | G7: =1250-F7 -> -27.3 | H7: 17222.2 | I7: =H8-H7 -> 307.6 | J7: 613792.5 | K7: =J8-J7 -> 1112.3 | L7: =I7+K7 -> 1419.9 | M7: =1450-L7 -> 30.1 | T7: 333907.9 | U7: 225523.4 | V7: 1300989 | W7: =(T7-T6)+(U7-U6)+(V7-V6) -> 2024.4 | X7: =2200-W7 -> 175.6
A8: 46177 | B8: 370465.3 | C8: =B9-B8 -> 434.2 | D8: 467318.7 | E8: =D9-D8 -> 304.4 | F8: =C8+E8 -> 738.6 | G8: =1250-F8 -> 511.4 | H8: 17529.8 | I8: =H9-H8 -> 309.6 | J8: 614904.8 | K8: =J9-J8 -> 1089 | L8: =I8+K8 -> 1398.6 | M8: =1450-L8 -> 51.4 | T8: 334286.7 | U8: 225756 | V8: 1302358 | W8: =(T8-T7)+(U8-U7)+(V8-V7) -> 1980.4 | X8: =2200-W8 -> 219.6
A9: 46207 | B9: 370899.5 | C9: =B10-B9 -> 406.3 | D9: 467623.1 | E9: =D10-D9 -> 555.4 | F9: =C9+E9 -> 961.7 | G9: =1250-F9 -> 288.3 | H9: 17839.4 | I9: =H10-H9 -> 309 | J9: 615993.8 | K9: =J10-J9 -> 1051.5 | L9: =I9+K9 -> 1360.5 | M9: =1450-L9 -> 89.5 | N9: 206145 | O9: =N10-N9 -> 458.5 | P9: 290594 | Q9: =P10-P9 -> 597.8 | R9: =O9+Q9 -> 1056.3 | S9: =1250-Sheet1!R9 -> 193.7 | T9: 334666.1 | U9: 225988.7 | V9: 1303732 | W9: =(T9-T8)+(U9-U8)+(V9-V8) -> 1986.1 | X9: =2200-W9 -> 213.9
A10: 46238 | B10: 371305.8 | C10: =B11-B10 -> 569.6 | D10: 468178.5 | E10: =D11-D10 -> 612.1 | F10: =C10+E10 -> 1181.7 | G10: =1250-F10 -> 68.3 | H10: 18148.4 | I10: =H11-H10 -> 305.7 | J10: 617045.3 | K10: =J11-J10 -> 837.2 | L10: =I10+K10 -> 1142.9 | M10: =1450-L10 -> 307.1 | N10: 206603.5 | O10: =N11-N10 -> 441.2 | P10: 291191.8 | Q10: =P11-P10 -> 605.3 | R10: =O10+Q10 -> 1046.5 | S10: =1250-Sheet1!R10 -> 203.5 | T10: 335045.7 | U10: 226221.2 | V10: 1305103 | W10: =(T10-T9)+(U10-U9)+(V10-V9) -> 1983.1 | X10: =2200-W10 -> 216.9
A11: 46269 | B11: 371875.4 | C11: =B12-B11 -> 591.3 | D11: 468790.6 | E11: =D12-D11 -> 777.2 | F11: =C11+E11 -> 1368.5 | G11: =1250-F11 -> -118.5 | H11: 18454.1 | I11: =H12-H11 -> 301.5 | J11: 617882.5 | K11: =J12-J11 -> 1072.1 | L11: =I11+K11 -> 1373.6 | M11: =1450-L11 -> 76.4 | N11: 207044.7 | O11: =N12-N11 -> 476.6 | P11: 291797.1 | Q11: =P12-P11 -> 581.1 | R11: =O11+Q11 -> 1057.7 | S11: =1250-Sheet1!R11 -> 192.3 | T11: 335418.9 | U11: 226449.3 | V11: 1306447 | W11: =(T11-T10)+(U11-U10)+(V11-V10) -> 1945.3 | X11: =2200-W11 -> 254.7
A12: 46299 | B12: 372466.7 | C12: =B13-B12 -> 591.8 | D12: 469567.8 | E12: =D13-D12 -> 746.3 | F12: =C12+E12 -> 1338.1 | G12: =1250-F12 -> -88.1 | H12: 18755.6 | I12: =H13-H12 -> 385.9 | J12: 618954.6 | K12: =J13-J12 -> 1148.3 | L12: =I12+K12 -> 1534.2 | M12: =1450-L12 -> -84.2 | N12: 207521.3 | O12: =N13-N12 -> 427 | P12: 292378.2 | Q12: =P13-P12 -> 400.1 | R12: =O12+Q12 -> 827.1 | S12: =1250-Sheet1!R12 -> 422.9 | T12: 335798.5 | U12: 226681.1 | V12: 1307812 | W12: =(T12-T11)+(U12-U11)+(V12-V11) -> 1976.4 | X12: =2200-W12 -> 223.6
A13: 46330 | B13: 373058.5 | C13: =B14-B13 -> 591.3 | D13: 470314.1 | E13: =D14-D13 -> 760 | F13: =C13+E13 -> 1351.3 | G13: =1250-F13 -> -101.3 | H13: 19141.5 | I13: =H14-H13 -> 364.8 | J13: 620102.9 | K13: =J14-J13 -> 1028.3 | L13: =I13+K13 -> 1393.1 | M13: =1450-L13 -> 56.9 | N13: 207948.3 | O13: =N14-N13 -> 117.6 | P13: 292778.3 | Q13: =P14-P13 -> 17.9 | R13: =O13+Q13 -> 135.5 | S13: =1250-Sheet1!R13 -> 1114.5 | T13: 336178.8 | U13: 226913.5 | V13: 1309205 | W13: =(T13-T12)+(U13-U12)+(V13-V12) -> 2005.7 | X13: =2200-W13 -> 194.3
A14: 46360 | B14: 373649.8 | C14: =B15-B14 -> 590 | D14: 471074.1 | E14: =D15-D14 -> 500 | F14: =C14+E14 -> 1090 | G14: =1250-F14 -> 160 | H14: 19506.3 | I14: =H15-H14 -> 205.1 | J14: 621131.2 | K14: =J15-J14 -> 421.4 | L14: =I14+K14 -> 626.5 | M14: =1450-L14 -> 823.5 | N14: 208065.9 | O14: =N15-N14 -> 14.2 | P14: 292796.2 | Q14: =P15-P14 -> 51.1 | R14: =O14+Q14 -> 65.3 | S14: =1250-Sheet1!R14 -> 1184.7 | T14: 336559.3 | U14: 227146.3 | V14: 1310611 | W14: =(T14-T13)+(U14-U13)+(V14-V13) -> 2019.3 | X14: =2200-W14 -> 180.7
A15: 13/4/2026 | B15: 374239.8 | C15: =B16-B15 -> 590 | D15: 471574.1 | E15: =D16-D15 -> 758.4 | F15: =C15+E15 -> 1348.4 | G15: =1250-F15 -> -98.4 | H15: 19711.4 | I15: =H16-H15 -> 324.3 | J15: 621552.6 | K15: =J16-J15 -> 880.2 | L15: =I15+K15 -> 1204.5 | M15: =1450-L15 -> 245.5 | N15: 208080.1 | O15: =N16-N15 -> 463.7 | P15: 292847.3 | Q15: =P16-P15 -> 473.1 | R15: =O15+Q15 -> 936.8 | S15: =1250-Sheet1!R15 -> 313.2 | T15: 336938.5 | U15: 227378.4 | V15: 1312003 | W15: =(T15-T14)+(U15-U14)+(V15-V14) -> 2003.3 | X15: =2200-W15 -> 196.7
A16: 14/4/2026 | B16: 374829.8 | C16: =B17-B16 -> 588.2 | D16: 472332.5 | E16: =D17-D16 -> 704 | F16: =C16+E16 -> 1292.2 | G16: =1250-F16 -> -42.2 | H16: 20035.7 | I16: =H17-H16 -> 357.2 | J16: 622432.8 | K16: =J17-J16 -> 1124.2 | L16: =I16+K16 -> 1481.4 | M16: =1450-L16 -> -31.4 | N16: 208543.8 | O16: =N17-N16 -> 397.6 | P16: 293320.4 | Q16: =P17-P16 -> 391.4 | R16: =O16+Q16 -> 789 | S16: =1250-Sheet1!R16 -> 461 | T16: 337314.7 | U16: 227610.5 | V16: 1313418 | W16: =(T16-T15)+(U16-U15)+(V16-V15) -> 2023.3 | X16: =2200-W16 -> 176.7
A17: 15/4/2026 | B17: 375418 | C17: =B18-B17 -> 490.9 | D17: 473036.5 | E17: =D18-D17 -> 327 | F17: =C17+E17 -> 817.9 | G17: =1250-F17 -> 432.1 | H17: 20392.9 | I17: =H18-H17 -> 349.5 | J17: 623557 | K17: =J18-J17 -> 1026.4 | L17: =I17+K17 -> 1375.9 | M17: =1450-L17 -> 74.1 | N17: 208941.4 | O17: =N18-N17 -> 401.5 | P17: 293711.8 | Q17: =P18-P17 -> 496.7 | R17: =O17+Q17 -> 898.2 | S17: =1250-Sheet1!R17 -> 351.8 | T17: 337694.1 | U17: 227841.9 | V17: 1314770 | W17: =(T17-T16)+(U17-U16)+(V17-V16) -> 1962.8 | X17: =2200-W17 -> 237.2
A18: 16/04/2026 | B18: 375908.9 | C18: =B19-B18 -> 220.7 | D18: 473363.5 | E18: =D19-D18 -> 10 | F18: =C18+E18 -> 230.7 | G18: =1250-F18 -> 1019.3 | H18: 20742.4 | I18: =H19-H18 -> 352.5 | J18: 624583.4 | K18: =J19-J18 -> 1142.4 | L18: =I18+K18 -> 1494.9 | M18: =1450-L18 -> -44.9 | N18: 209342.9 | O18: =N19-N18 -> 390.3 | P18: 294208.5 | Q18: =P19-P18 -> 452.6 | R18: =O18+Q18 -> 842.9 | S18: =1250-Sheet1!R18 -> 407.1 | T18: 338073.9 | U18: 228073.3 | V18: 1316090 | W18: =(T18-T17)+(U18-U17)+(V18-V17) -> 1931.2 | X18: =2200-W18 -> 268.8
A19: 17/04/2026 | B19: 376129.6 | C19: =B20-B19 -> 0 | D19: 473373.5 | E19: =D20-D19 -> 0 | F19: =C19+E19 -> 0 | G19: =1250-F19 -> 1250 | H19: 21094.9 | I19: =H20-H19 -> 344.2 | J19: 625725.8 | K19: =J20-J19 -> 1113.8 | L19: =I19+K19 -> 1458 | M19: =1450-L19 -> -8 | N19: 209733.2 | O19: =N20-N19 -> 426.7 | P19: 294661.1 | Q19: =P20-P19 -> 529.7 | R19: =O19+Q19 -> 956.4 | S19: =1250-Sheet1!R19 -> 293.6 | T19: 338468.3 | U19: 228304.4 | V19: 1317558 | W19: =(T19-T18)+(U19-U18)+(V19-V18) -> 2093.5 | X19: =2200-W19 -> 106.5
A20: 18/04/2026 | B20: 376129.6 | C20: =B21-B20 -> 0 | D20: 473373.5 | E20: =D21-D20 -> 0 | F20: =C20+E20 -> 0 | G20: =1250-F20 -> 1250 | H20: 21439.1 | I20: =H21-H20 -> 349.2 | J20: 626839.6 | K20: =J21-J20 -> 1040.4 | L20: =I20+K20 -> 1389.6 | M20: =1450-L20 -> 60.4 | N20: 210159.9 | O20: =N21-N20 -> 424.7 | P20: 295190.8 | Q20: =P21-P20 -> 0 | R20: =O20+Q20 -> 424.7 | S20: =1250-Sheet1!R20 -> 825.3 | T20: 338852 | U20: 228529.7 | V20: 1318769 | W20: =(T20-T19)+(U20-U19)+(V20-V19) -> 1820 | X20: =2200-W20 -> 380
A21: 19/04/2026 | B21: 376129.6 | C21: =B22-B21 -> 0 | D21: 473373.5 | E21: =D22-D21 -> 0 | F21: =C21+E21 -> 0 | G21: =1250-F21 -> 1250 | H21: 21788.3 | I21: =H22-H21 -> 310.5 | J21: 627880 | K21: =J22-J21 -> 810.9 | L21: =I21+K21 -> 1121.4 | M21: =1450-L21 -> 328.6 | N21: 210584.6 | O21: =N22-N21 -> 0 | P21: 295190.8 | Q21: =P22-P21 -> 889.5 | R21: =O21+Q21 -> 889.5 | S21: =1250-Sheet1!R21 -> 360.5 | T21: 339227.7 | U21: 228759.4 | V21: 1319730 | W21: =(T21-T20)+(U21-U20)+(V21-V20) -> 1566.4 | X21: =2200-W21 -> 633.6
A22: 20/04/2026 | B22: 376129.6 | C22: 0 | D22: 473373.5 | E22: 0 | F22: =C22+E22 -> 0 | G22: =1250-F22 -> 1250 | H22: 22098.8 | I22: =H23-H22 -> 356.8 | J22: 628690.9 | K22: =J23-J22 -> 1126.7 | L22: =I22+K22 -> 1483.5 | M22: =1450-L22 -> -33.5 | N22: 210584.6 | O22: =N23-N22 -> 856.1 | P22: 296080.3 | Q22: =P23-P22 -> 473.3 | R22: =O22+Q22 -> 1329.4 | S22: =1250-Sheet1!R22 -> -79.4 | T22: 339561.6 | U22: 228966.8 | V22: 1320724 | W22: =(T22-T21)+(U22-U21)+(V22-V21) -> 1535.3 | X22: =2200-W22 -> 664.7
A23: 21/04/2026 | B23: 376356.3 | C23: =B24-B23 -> 526.4 | D23: 473773.2 | E23: =D24-D23 -> 715.9 | F23: =C23+E23 -> 1242.3 | G23: =1250-F23 -> 7.7 | H23: 22455.6 | I23: =H24-H23 -> 365.3 | J23: 629817.6 | K23: =J24-J23 -> 1091.9 | L23: =I23+K23 -> 1457.2 | M23: =1450-L23 -> -7.2 | N23: 211440.7 | O23: =N24-N23 -> 0 | P23: 296553.6 | Q23: =P24-P23 -> 0 | R23: =O23+Q23 -> 0 | S23: =1250-Sheet1!R23 -> 1250 | T23: 339936.8 | U23: 229197.1 | V23: 1321884 | W23: =(T23-T22)+(U23-U22)+(V23-V22) -> 1765.5 | X23: =2200-W23 -> 434.5
A24: 22/04/2026 | B24: 376882.7 | C24: =B25-B24 -> 574.5 | D24: 474489.1 | E24: =D25-D24 -> 670.9 | F24: =C24+E24 -> 1245.4 | G24: =1250-F24 -> 4.6 | H24: 22820.9 | I24: =H25-H24 -> 365 | J24: 630909.5 | K24: =J25-J24 -> 1070.4 | L24: =I24+K24 -> 1435.4 | M24: =1450-L24 -> 14.6 | N24: 211440.7 | O24: =N25-N24 -> 649.8 | P24: 296553.6 | Q24: =P25-P24 -> 956.5 | R24: =O24+Q24 -> 1606.3 | S24: =1250-Sheet1!R24 -> -356.3 | T24: 340361.8 | U24: 229427.8 | V24: 1323301 | W24: =(T24-T23)+(U24-U23)+(V24-V23) -> 2072.7 | X24: =2200-W24 -> 127.3
A25: 23/04/2026 | B25: 377457.2 | C25: =B26-B25 -> 573 | D25: 475160 | E25: =D26-D25 -> 755.2 | F25: =C25+E25 -> 1328.2 | G25: =1250-F25 -> -78.2 | H25: 23185.9 | I25: =H26-H25 -> 330.9 | J25: 631979.9 | K25: =J26-J25 -> 974.7 | L25: =I25+K25 -> 1305.6 | M25: =1450-L25 -> 144.4 | N25: 212090.5 | O25: =N26-N25 -> 457.8 | P25: 297510.1 | Q25: =P26-P25 -> 615.3 | R25: =O25+Q25 -> 1073.1 | S25: =1250-Sheet1!R25 -> 176.9 | T25: 340764.6 | U25: 229657.9 | V25: 1324783 | W25: =(T25-T24)+(U25-U24)+(V25-V24) -> 2114.9 | X25: =2200-W25 -> 85.1
A26: 24/04/2026 | B26: 378030.2 | C26: =B27-B26 -> 575.5 | D26: 475915.2 | E26: =D27-D26 -> 731.9 | F26: =C26+E26 -> 1307.4 | G26: =1250-F26 -> -57.4 | H26: 23516.8 | I26: =H27-H26 -> 354.8 | J26: 632954.6 | K26: =J27-J26 -> 1025.2 | L26: =I26+K26 -> 1380 | M26: =1450-L26 -> 70 | N26: 212548.3 | O26: =N27-N26 -> 433 | P26: 298125.4 | Q26: =P27-P26 -> 483.6 | R26: =O26+Q26 -> 916.6 | S26: =1250-Sheet1!R26 -> 333.4 | T26: 341141.2 | U26: 229888.7 | V26: 1326260 | W26: =(T26-T25)+(U26-U25)+(V26-V25) -> 2084.4 | X26: =2200-W26 -> 115.6
A27: 25/04/2026 | B27: 378605.7 | C27: =B28-B27 -> 520.2 | D27: 476647.1 | E27: =D28-D27 -> 686.7 | F27: =C27+E27 -> 1206.9 | G27: =1250-F27 -> 43.1 | H27: 23871.6 | I27: =H28-H27 -> 338.4 | J27: 633979.8 | K27: =J28-J27 -> 637.6 | L27: =I27+K27 -> 976 | M27: =1450-L27 -> 474 | N27: 212981.3 | O27: =N28-N27 -> 415.5 | P27: 298609 | Q27: =P28-P27 -> 615.2 | R27: =O27+Q27 -> 1030.7 | S27: =1250-Sheet1!R27 -> 219.3 | T27: 341518.4 | U27: 230120.3 | V27: 1327735 | W27: =(T27-T26)+(U27-U26)+(V27-V26) -> 2083.8 | X27: =2200-W27 -> 116.2
A28: 26/04/2026 | B28: 379125.9 | C28: =B29-B28 -> 456.8 | D28: 477333.8 | E28: =D29-D28 -> 446.7 | F28: =C28+E28 -> 903.5 | G28: =1250-F28 -> 346.5 | H28: 24210 | I28: =H29-H28 -> 261.4 | J28: 634617.4 | K28: =J29-J28 -> 569.9 | L28: =I28+K28 -> 831.3 | M28: =1450-L28 -> 618.7 | N28: 213396.8 | O28: =N29-N28 -> 254.8 | P28: 299224.2 | Q28: =P29-P28 -> 328.5 | R28: =O28+Q28 -> 583.3 | S28: =1250-Sheet1!R28 -> 666.7 | T28: 341878.8 | U28: 230346 | V28: 1329063 | W28: =(T28-T27)+(U28-U27)+(V28-V27) -> 1914.1 | X28: =2200-W28 -> 285.9
A29: 27/04/2026 | B29: 379582.7 | C29: =B30-B29 -> 458.7 | D29: 477780.5 | E29: =D30-D29 -> 534.5 | F29: =C29+E29 -> 993.2 | G29: =1250-F29 -> 256.8 | H29: 24471.4 | I29: =H30-H29 -> 310.7 | J29: 635187.3 | K29: =J30-J29 -> 766.8 | L29: =I29+K29 -> 1077.5 | M29: =1450-L29 -> 372.5 | N29: 213651.6 | O29: =N30-N29 -> 294.4 | P29: 299552.7 | Q29: =P30-P29 -> 414.9 | R29: =O29+Q29 -> 709.3 | S29: =1250-Sheet1!R29 -> 540.7 | T29: 342256.8 | U29: 230578.8 | V29: 1330441 | W29: =(T29-T28)+(U29-U28)+(V29-V28) -> 1988.8 | X29: =2200-W29 -> 211.2
A30: 28/04/2026 | B30: 380041.4 | C30: =B31-B30 -> 455.5 | D30: 478315 | E30: =D31-D30 -> 513 | F30: =C30+E30 -> 968.5 | G30: =1250-F30 -> 281.5 | H30: 24782.1 | I30: =H31-H30 -> 329.7 | J30: 635954.1 | K30: =J31-J30 -> 986.6 | L30: =I30+K30 -> 1316.3 | M30: =1450-L30 -> 133.7 | N30: 213946 | O30: =N31-N30 -> 230.6 | P30: 299967.6 | Q30: =P31-P30 -> 236.2 | R30: =O30+Q30 -> 466.8 | S30: =1250-Sheet1!R30 -> 783.2 | T30: 342634.1 | U30: 230810.1 | V30: 1331519 | W30: =(T30-T29)+(U30-U29)+(V30-V29) -> 1686.6 | X30: =2200-W30 -> 513.4
A31: 29/04/2026 | B31: 380496.9 | C31: =B32-B31 -> 455.4 | D31: 478828 | E31: =D32-D31 -> 533.2 | F31: =C31+E31 -> 988.6 | G31: =1250-F31 -> 261.4 | H31: 25111.8 | I31: =H32-H31 -> 317.8 | J31: 636940.7 | K31: =J32-J31 -> 864.1 | L31: =I31+K31 -> 1181.9 | M31: =1450-L31 -> 268.1 | N31: 214176.6 | O31: =N32-N31 -> 0 | P31: 300203.8 | Q31: =P32-P31 -> 17.7 | R31: =O31+Q31 -> 17.7 | S31: =1250-Sheet1!R31 -> 1232.3 | T31: 343011.2 | U31: 231041.6 | V31: 1332606 | W31: =(T31-T30)+(U31-U30)+(V31-V30) -> 1695.6 | X31: =2200-W31 -> 504.4
A32: 30/04/2026 | B32: 380952.3 | C32: =B33-B32 -> 454.1 | D32: 479361.2 | E32: =D33-D32 -> 492.7 | F32: =C32+E32 -> 946.8 | G32: =1250-F32 -> 303.2 | H32: 25429.6 | I32: =H33-H32 -> 308.9 | J32: 637804.8 | K32: =J33-J32 -> 891.6 | L32: =I32+K32 -> 1200.5 | M32: =1450-L32 -> 249.5 | N32: 214176.6 | O32: =N33-N32 -> 0 | P32: 300221.5 | Q32: =P33-P32 -> 17.9 | R32: =O32+Q32 -> 17.9 | S32: =1250-Sheet1!R32 -> 1232.1 | T32: 343388.3 | U32: 231272.9 | V32: 1333918 | W32: =(T32-T31)+(U32-U31)+(V32-V31) -> 1920.4 | X32: =2200-W32 -> 279.6
A33: 46143 | B33: 381406.4 | C33: =B34-B33 -> 449.5 | D33: 479853.9 | E33: =D34-D33 -> 431.2 | F33: =C33+E33 -> 880.7 | G33: =1250-F33 -> 369.3 | H33: 25738.5 | I33: =H34-H33 -> 299 | J33: 638696.4 | K33: =J34-J33 -> 892.3 | L33: =I33+K33 -> 1191.3 | M33: =1450-L33 -> 258.7 | N33: 214176.6 | O33: =N34-N33 -> 0.1 | P33: 300239.4 | Q33: =P34-P33 -> 19.7 | R33: =O33+Q33 -> 19.8 | S33: =1250-Sheet1!R33 -> 1230.2 | T33: 343765.4 | U33: 231504.1 | V33: 1335578 | W33: =(T33-T32)+(U33-U32)+(V33-V32) -> 2268.3 | X33: =2200-W33 -> -68.3
A34: 46144 | B34: 381855.9 | C34: =B35-B34 -> 447.3 | D34: 480285.1 | E34: =D35-D34 -> 499.9 | F34: =C34+E34 -> 947.2 | G34: =1250-F34 -> 302.8 | H34: 26037.5 | I34: =H35-H34 -> 338.8 | J34: 639588.7 | K34: =J35-J34 -> 823.3 | L34: =I34+K34 -> 1162.1 | M34: =1450-L34 -> 287.9 | N34: 214176.7 | O34: =N35-N34 -> 0 | P34: 300259.1 | Q34: =P35-P34 -> 0 | R34: =O34+Q34 -> 0 | S34: =1250-Sheet1!R34 -> 1250 | T34: 344137 | U34: 231730.4 | V34: 1337131 | W34: =(T34-T33)+(U34-U33)+(V34-V33) -> 2150.9 | X34: =2200-W34 -> 49.1
A35: 46145 | B35: 382303.2 | C35: =B36-B35 -> 298.8 | D35: 480785 | E35: =D36-D35 -> 326.5 | F35: =C35+E35 -> 625.3 | G35: =1250-F35 -> 624.7 | H35: 26376.3 | I35: =H36-H35 -> 216.4 | J35: 640412 | K35: =J36-J35 -> 573.8 | L35: =I35+K35 -> 790.2 | M35: =1450-L35 -> 659.8 | N35: 214176.7 | O35: =N36-N35 -> 0 | P35: 300259.1 | Q35: =P36-P35 -> 0 | R35: =O35+Q35 -> 0 | S35: =1250-Sheet1!R35 -> 1250 | T35: 344508.3 | U35: 231957 | V35: 1338701 | W35: =(T35-T34)+(U35-U34)+(V35-V34) -> 2167.9 | X35: =2200-W35 -> 32.1
A36: 46146 | B36: 382602 | C36: =B37-B36 -> 369 | D36: 481111.5 | E36: =D37-D36 -> 439.1 | F36: =C36+E36 -> 808.1 | G36: =1250-F36 -> 441.9 | H36: 26592.7 | I36: =H37-H36 -> 264 | J36: 640985.8 | K36: =J37-J36 -> 1133 | L36: =I36+K36 -> 1397 | M36: =1450-L36 -> 53 | N36: 214176.7 | O36: =N37-N36 -> 0 | P36: 300259.1 | Q36: =P37-P36 -> 0 | R36: =O36+Q36 -> 0 | S36: =1250-Sheet1!R36 -> 1250 | T36: 344898.5 | U36: 232159.1 | V36: 1340375 | W36: =(T36-T35)+(U36-U35)+(V36-V35) -> 2266.3 | X36: =2200-W36 -> -66.3
A37: 46147 | B37: 382971 | C37: =B38-B37 -> 452.4 | D37: 481550.6 | E37: =D38-D37 -> 520 | F37: =C37+E37 -> 972.4 | G37: =1250-F37 -> 277.6 | H37: 26856.7 | I37: =H38-H37 -> 342.5 | J37: 642118.8 | K37: =J38-J37 -> 1310.5 | L37: =I37+K37 -> 1653 | M37: =1450-L37 -> -203 | N37: 214176.7 | O37: =N38-N37 -> 0 | P37: 300259.1 | Q37: =P38-P37 -> 0 | R37: =O37+Q37 -> 0 | S37: =1250-Sheet1!R37 -> 1250 | T37: 345274.1 | U37: 232384.1 | V37: 1341940 | W37: =(T37-T36)+(U37-U36)+(V37-V36) -> 2165.6 | X37: =2200-W37 -> 34.4
A38: 46148 | B38: 383423.4 | C38: =B39-B38 -> 430.6 | D38: 482070.6 | E38: =D39-D38 -> 545.9 | F38: =C38+E38 -> 976.5 | G38: =1250-F38 -> 273.5 | H38: 27199.2 | I38: =H39-H38 -> 325 | J38: 643429.3 | K38: =J39-J38 -> 1225 | L38: =I38+K38 -> 1550 | M38: =1450-L38 -> -100 | N38: 214176.7 | O38: =N39-N38 -> 0 | P38: 300259.1 | Q38: =P39-P38 -> 0 | R38: =O38+Q38 -> 0 | S38: =1250-Sheet1!R38 -> 1250 | T38: 345640.8 | U38: 232614.6 | V38: 1343740 | W38: =(T38-T37)+(U38-U37)+(V38-V37) -> 2397.2 | X38: =2200-W38 -> -197.2
A39: 46149 | B39: 383854 | C39: =B40-B39 -> 403.6 | D39: 482616.5 | E39: =D40-D39 -> 474.2 | F39: =C39+E39 -> 877.8 | G39: =1250-F39 -> 372.2 | H39: 27524.2 | I39: =H40-H39 -> 293.5 | J39: 644654.3 | K39: =J40-J39 -> 995.9 | L39: =I39+K39 -> 1289.4 | M39: =1450-L39 -> 160.6 | N39: 214176.7 | O39: =N40-N39 -> 304.4 | P39: 300259.1 | Q39: =P40-P39 -> 455.8 | R39: =O39+Q39 -> 760.2 | S39: =1250-Sheet1!R39 -> 489.8 | T39: 346020 | U39: 232846.8 | V39: 1345425 | W39: =(T39-T38)+(U39-U38)+(V39-V38) -> 2296.4 | X39: =2200-W39 -> -96.4
A40: 46150 | B40: 384257.6 | C40: =B41-B40 -> 389.7 | D40: 483090.7 | E40: =D41-D40 -> 513.9 | F40: =C40+E40 -> 903.6 | G40: =1250-F40 -> 346.4 | H40: 27817.7 | I40: =H41-H40 -> 271.6 | J40: 645650.2 | K40: =J41-J40 -> 932.2 | L40: =I40+K40 -> 1203.8 | M40: =1450-L40 -> 246.2 | N40: 214481.1 | O40: =N41-N40 -> 313.8 | P40: 300714.9 | Q40: =P41-P40 -> 407.7 | R40: =O40+Q40 -> 721.5 | S40: =1250-Sheet1!R40 -> 528.5 | T40: 346397.3 | U40: 233077.1 | V40: 1347094 | W40: =(T40-T39)+(U40-U39)+(V40-V39) -> 2276.6 | X40: =2200-W40 -> -76.6
...

Sheet Sheet2
A1: Running hrs of All the Cold storage units
A2: CLC-Blast | E2: BMC- Blast | I2: Dunkin - Blast | M2: Paneer Tikka - Old CK - Blast | P2: Old CK New Blast -2 | S2: New Ck GF- Blast | V2: New CK 1st F - Blast
A3: From | B3: To | C3: Running Hrs. | D3: KWH | E3: From | F3: To | G3: Running Hrs. | H3: KWH | I3: From | J3: To | K3: Running Hrs. | L3: KWH | M3: From | N3: To | O3: Running Hrs. | P3: From | Q3: To | R3: Running Hrs. | S3: From | T3: To | U3: Running Hrs. | V3: From | W3: To | X3: Running Hrs.
A4: 46124 | B4: 46124.542 | C4: =B4-A4 -> 0.54166667 | D4: 626.5 | E4: 46124.958 | F4: 46125 | G4: =F4-E4 -> 0.041655093 | H4: 65.3 | I4: 46124 | J4: 46125 | K4: =J4-I4 -> 0.99998843 | L4: 1090 | M4: 46124 | N4: 46125 | O4: =N4-M4 -> 0.99998843 | S4: 46124.458 | T4: 46124.865 | U4: =T4-S4 -> 0.40693287 | X4: 0
A5: 46125 | B5: 46126 | C5: =B5-A5 -> 0.99998843 | D5: 1204.5 | E5: 46125 | F5: 46126 | G5: =F5-E5 -> 0.99998843 | H5: 936.8 | I5: 46125 | J5: 46126 | K5: =J5-I5 -> 0.99998837 | L5: 1348.4 | M5: 46125 | N5: 46126 | O5: =N5-M5 -> 0.99998837 | S5: 46125.458 | T5: 46125.872 | U5: =T5-S5 -> 0.41319444 | X5: 0
A6: 46126 | B6: 46127 | C6: =B6-A6 -> 0.99998843 | D6: 1481.4 | E6: 46126 | F6: 46126.743 | G6: =F6-E6 -> 0.74305556 | H6: 789 | I6: 46126 | J6: 46127 | K6: =J6-I6 -> 0.99998837 | L6: 1292.2 | M6: 46126 | N6: 46127 | O6: =N6-M6 -> 0.99998837 | S6: 46126.458 | T6: 46126.872 | U6: =T6-S6 -> 0.41319444 | X6: 0
A7: 46127 | B7: 46128 | C7: =B7-A7 -> 0.99998837 | D7: 1375.9 | E7: 46126.903 | F7: 46127 | G7: =F7-E7 -> 0.097210648 | I7: 46127 | J7: 46127.69 | K7: =J7-I7 -> 0.69027778 | L7: 817.9 | M7: 46127 | N7: 46128 | O7: =N7-M7 -> 0.99998837 | S7: 46127.458 | T7: 46128 | U7: =T7-S7 -> 0.54165509 | X7: 0
A8: 46128 | B8: 46129 | C8: =B8-A8 -> 0.99998837 | D8: 1494.9 | E8: 46127 | F8: 46127.176 | G8: =F8-E8 -> 0.17638889 | H8: 898.2 | I8: 46128 | J8: 46128 | K8: =J8-I8 -> 0 | L8: 230.7 | M8: 46128 | N8: 46129 | O8: =N8-M8 -> 0.99998837 | S8: 46128 | T8: 46129 | U8: =T8-S8 -> 0.99998837 | V8: 46128.792 | W8: 46129 | X8: =W8-V8 -> 0.2083217
A9: 46129 | B9: 46130 | C9: =B9-A9 -> 0.99998837 | D9: 1458 | E9: 46127.375 | F9: 46127.999 | G9: =F9-E9 -> 0.62430556 | I9: 46129 | J9: 46129.042 | K9: =J9-I9 -> 0.041666667 | L9: 0 | M9: 46129 | N9: 46130 | O9: =N9-M9 -> 0.99998837 | S9: 46129 | T9: 46130 | U9: =T9-S9 -> 0.99998837 | V9: 46129 | W9: 46130 | X9: =W9-V9 -> 0.99998837
A10: 46130 | B10: 46131 | C10: =B10-A10 -> 0.99998837 | D10: 1389.6 | E10: 46128 | F10: 46128.999 | G10: =F10-E10 -> 0.9993055 | H10: 842.9 | I10: 46130 | J10: 46130 | K10: =J10-I10 -> 0 | L10: 0 | M10: 46130 | N10: 46131 | O10: =N10-M10 -> 0.99998837 | S10: 46130 | T10: 46130.882 | U10: =T10-S10 -> 0.88194444 | V10: 46130 | W10: 46131 | X10: =W10-V10 -> 0.99998837
A11: 46131 | B11: 46132 | C11: =B11-A11 -> 0.99998837 | D11: 1121.4 | E11: 46129 | F11: 46129.999 | G11: =F11-E11 -> 0.9993055 | H11: 956.4 | I11: 46131 | J11: 46131 | K11: =J11-I11 -> 0 | L11: 0 | M11: 46131 | N11: 46132 | O11: =N11-M11 -> 0.99998837 | S11: 46131 | T11: 46131 | U11: =T11-S11 -> 0 | V11: 46131 | W11: 46132 | X11: =W11-V11 -> 0.99998837
A12: 46132 | B12: 46133 | C12: =B12-A12 -> 0.99998837 | D12: 1483.5 | E12: 46130 | F12: 46130.999 | G12: =F12-E12 -> 0.9993055 | H12: 424.7 | I12: 46132.647 | J12: 46133 | K12: =J12-I12 -> 0.35346065 | L12: 0 | M12: 46132 | N12: 46133 | O12: =N12-M12 -> 0.99998837 | S12: 46132.458 | T12: 46132.893 | U12: =T12-S12 -> 0.43471065 | V12: 46132 | W12: 46133 | X12: =W12-V12 -> 0.99998837
A13: 46133 | B13: 46134 | C13: =B13-A13 -> 0.99998837 | D13: 1457.2 | E13: 46131 | F13: 46131.999 | G13: =F13-E13 -> 0.9993055 | H13: 889.5 | I13: 46133 | J13: 46134 | K13: =J13-I13 -> 0.99998837 | L13: 1242.3 | M13: 46133 | N13: 46133.901 | O13: =N13-M13 -> 0.90068287 | S13: 46133.458 | T13: 46133.875 | U13: =T13-S13 -> 0.41666667 | V13: 46133 | W13: 46134 | X13: =W13-V13 -> 0.99998837
A14: 46134 | B14: 46135 | C14: =B14-A14 -> 0.99998837 | D14: 1435.4 | E14: 46132 | F14: 46132.999 | G14: =F14-E14 -> 0.9993055 | H14: 1329.4 | I14: 46134 | J14: 46135 | K14: =J14-I14 -> 0.99998837 | L14: 1245.4 | M14: 46134 | N14: 46134 | O14: =N14-M14 -> 0 | S14: 46134.479 | T14: 46134.861 | U14: =T14-S14 -> 0.38194444 | V14: 46134 | W14: 46135 | X14: =W14-V14 -> 0.99998837
A15: 46135 | B15: 46136 | C15: =B15-A15 -> 0.99998837 | D15: 1305.6 | E15: 46133 | F15: 46133.72 | G15: =F15-E15 -> 0.72013883 | H15: 0 | I15: 46135 | J15: 46136 | K15: =J15-I15 -> 0.99998837 | L15: 1328.2 | M15: 46135 | N15: 46135 | O15: =N15-M15 -> 0 | S15: 46135.479 | T15: 46135.906 | U15: =T15-S15 -> 0.42708333 | V15: 46135 | W15: 46136 | X15: =W15-V15 -> 0.99998837
A16: 46136 | B16: 46137 | C16: =B16-A16 -> 0.99998837 | D16: 1380 | E16: 46134.302 | F16: 46135 | G16: =F16-E16 -> 0.69790509 | H16: 1606.3 | I16: 46136 | J16: 46137 | K16: =J16-I16 -> 0.99998837 | L16: 1307.4 | M16: 46136 | N16: 46136 | O16: =N16-M16 -> 0 | S16: 46136.49 | T16: 46136.872 | U16: =T16-S16 -> 0.38194444 | V16: 46136 | W16: 46137 | X16: =W16-V16 -> 0.99998837
A17: 46137 | B17: 46138 | C17: =B17-A17 -> 0.99998843 | D17: 976 | E17: 46135 | F17: 46136 | G17: =F17-E17 -> 0.99998837 | H17: 1073.1 | I17: 46137 | J17: 46138 | K17: =J17-I17 -> 0.99998837 | L17: 1206.9 | M17: 46137 | N17: 46137 | O17: =N17-M17 -> 0 | P17: 46137.771 | Q17: 46138 | R17: =Q17-P17 -> 0.22915509 | S17: 46137.476 | T17: 46138 | U17: =T17-S17 -> 0.52429398 | V17: 46137 | W17: 46138 | X17: =W17-V17 -> 0.99998837
A18: 46138 | B18: 46138.165 | C18: =B18-A18 -> 0.16458333 | D18: 831.3 | E18: 46136 | F18: 46137 | G18: =F18-E18 -> 0.99998837 | H18: 916.6 | I18: 46138 | J18: 46139 | K18: =J18-I18 -> 0.99998837 | L18: 903.5 | M18: 46138 | N18: 46138 | O18: =N18-M18 -> 0 | P18: 46138 | Q18: 46139 | R18: =Q18-P18 -> 0.99998837 | S18: 46138 | T18: 46138.528 | U18: =T18-S18 -> 0.52777778 | V18: 46138 | W18: 46139 | X18: =W18-V18 -> 0.99998837
A19: 46138.381 | B19: 46139 | C19: =B19-A19 -> 0.61943287 | E19: 46137 | F19: 46138 | G19: =F19-E19 -> 0.99998837 | H19: 1030.7 | I19: 46139 | J19: 46140 | K19: =J19-I19 -> 0.99998837 | L19: 993.2 | M19: 46139 | N19: 46139 | O19: =N19-M19 -> 0 | P19: 46139 | Q19: 46140 | R19: =Q19-P19 -> 0.99998837 | S19: 46139.448 | T19: 46139.868 | U19: =T19-S19 -> 0.42013889 | V19: 46139 | W19: 46140 | X19: =W19-V19 -> 0.99998837
A20: 46139 | B20: 46139.167 | C20: =B20-A20 -> 0.16666667 | D20: 1077.5 | E20: 46138 | F20: 46138.609 | G20: =F20-E20 -> 0.60902778 | H20: 583.3 | I20: 46140 | J20: 46141 | K20: =J20-I20 -> 0.99998837 | L20: 968.5 | M20: 46140 | N20: 46140 | O20: =N20-M20 -> 0 | P20: 46140 | Q20: 46141 | R20: =Q20-P20 -> 0.99998837 | S20: 46140.49 | U20: =T20-S20 -> -46140.49 | V20: 46140 | W20: 46141 | X20: =W20-V20 -> 0.99998837
A21: 46139.292 | B21: 46140 | C21: =B21-A21 -> 0.70832176 | E21: 46139.302 | F21: 46140 | G21: =F21-E21 -> 0.69790509 | H21: 709.3 | I21: 46141 | J21: 46142 | K21: =J21-I21 -> 0.99998837 | L21: 988.6 | M21: 46141 | N21: 46141 | O21: =N21-M21 -> 0 | P21: 46141 | Q21: 46142 | R21: =Q21-P21 -> 0.99998837 | V21: 46141 | W21: 46142 | X21: =W21-V21 -> 0.99998837
A22: 46140 | B22: 46140.167 | C22: =B22-A22 -> 0.16666667 | D22: 1316.3 | E22: 46140 | F22: 46140.522 | G22: =F22-E22 -> 0.5215162 | H22: 466.8 | I22: 46142 | J22: 46143 | K22: =J22-I22 -> 0.99998837 | L22: 946.8 | M22: 46142 | N22: 46142 | O22: =N22-M22 -> 0 | P22: 46142 | Q22: 46143 | R22: =Q22-P22 -> 0.99998837 | V22: 46142 | W22: 46143 | X22: =W22-V22 -> 0.99998837
A23: 46140.292 | B23: 46141 | C23: =B23-A23 -> 0.70832176 | E23: 46141 | F23: 46141 | G23: =F23-E23 -> 0 | H23: 17.7 | I23: 46143 | J23: 46144 | K23: =J23-I23 -> 0.99998837 | L23: 880.7 | M23: 46143 | N23: 46143 | O23: =N23-M23 -> 0 | P23: 46143 | Q23: 46144 | R23: =Q23-P23 -> 0.99998837 | V23: 46143 | W23: 46144 | X23: =W23-V23 -> 0.99998837
A24: 46141 | B24: 46141.167 | C24: =B24-A24 -> 0.16666667 | D24: 1181.9 | E24: 46142 | F24: 46142 | G24: =F24-E24 -> 0 | H24: 17.9 | I24: 46144 | J24: 46145 | K24: =J24-I24 -> 0.99998837 | L24: 947.2 | M24: 46144 | N24: 46144 | O24: =N24-M24 -> 0 | P24: 46144 | Q24: 46145 | R24: =Q24-P24 -> 0.99998837 | V24: 46144 | W24: 46145 | X24: =W24-V24 -> 0.99998837
A25: 46141.292 | B25: 46142 | C25: =B25-A25 -> 0.70832176 | E25: 46143 | F25: 46143 | G25: =F25-E25 -> 0 | H25: 19.8 | I25: 46145 | J25: 46146 | K25: =J25-I25 -> 0.99998837 | L25: 625.3 | M25: 46145 | N25: 46145 | O25: =N25-M25 -> 0 | P25: 46145 | Q25: 46146 | R25: =Q25-P25 -> 0.99998837 | V25: 46145 | W25: 46146 | X25: =W25-V25 -> 0.99998837
A26: 46142 | B26: 46142.167 | C26: =B26-A26 -> 0.16666667 | D26: 1200.5 | E26: 46144 | F26: 46144 | G26: =F26-E26 -> 0 | H26: 0 | I26: 46146 | J26: 46146.167 | K26: =J26-I26 -> 0.16666667 | L26: 808.1 | M26: 46146 | N26: 46146 | O26: =N26-M26 -> 0 | P26: 46146 | Q26: 46147 | R26: =Q26-P26 -> 0.99998837 | V26: 46146 | W26: 46147 | X26: =W26-V26 -> 0.99998837
A27: 46142.292 | B27: 46143 | C27: =B27-A27 -> 0.70832176 | E27: 46145 | F27: 46145 | G27: =F27-E27 -> 0 | H27: 0 | I27: 46146.292 | J27: 46147 | K27: =J27-I27 -> 0.70832176 | M27: 46147 | N27: 46147 | O27: =N27-M27 -> 0 | P27: 46147 | Q27: 46148 | R27: =Q27-P27 -> 0.99998837 | V27: 46147 | W27: 46148 | X27: =W27-V27 -> 0.99998837
A28: 46143 | B28: 46143.167 | C28: =B28-A28 -> 0.16666667 | D28: 1191.3 | E28: 46146 | F28: 46146 | G28: =F28-E28 -> 0 | H28: 0 | I28: 46147 | J28: 46148 | K28: =J28-I28 -> 0.99998843 | L28: 972.4 | M28: 46148 | N28: 46148 | O28: =N28-M28 -> 0 | P28: 46148 | Q28: 46149 | R28: =Q28-P28 -> 0.99998837 | V28: 46148 | W28: 46149 | X28: =W28-V28 -> 0.99998837
A29: 46143.292 | B29: 46144 | C29: =B29-A29 -> 0.70832176 | E29: 46147 | F29: 46147 | G29: =F29-E29 -> 0 | H29: 0 | I29: 46148 | J29: 46149 | K29: =J29-I29 -> 0.99998843 | L29: 976.5 | M29: 46149 | N29: 46149 | O29: =N29-M29 -> 0 | P29: 46149 | Q29: 46150 | R29: =Q29-P29 -> 0.99998837 | V29: 46149 | W29: 46150 | X29: =W29-V29 -> 0.99998837
A30: 46144 | B30: 46144.167 | C30: =B30-A30 -> 0.16666667 | D30: 1162.1 | E30: 46148 | F30: 46148 | G30: =F30-E30 -> 0 | H30: 0 | I30: 46149 | J30: 46149.167 | K30: =J30-I30 -> 0.16666667 | L30: 877.8 | M30: 46150 | N30: 46150 | O30: =N30-M30 -> 0 | P30: 46150 | R30: =Q30-P30 -> -46150 | V30: 46150 | X30: =W30-V30 -> -46150
A31: 46144.292 | B31: 46145 | C31: =B31-A31 -> 0.70832176 | E31: 46149.531 | F31: 46150 | G31: =F31-E31 -> 0.46873843 | H31: 760.2 | I31: 46149.292 | J31: 46150 | K31: =J31-I31 -> 0.70832176 | O31: =N31-M31 -> 0 | R31: =Q31-P31 -> 0 | X31: =W31-V31 -> 0
A32: 46145 | B32: 46145.167 | C32: =B32-A32 -> 0.16666667 | D32: 790.2 | E32: 46150 | F32: 46150.167 | G32: =F32-E32 -> 0.16665509 | H32: =Sheet1!R40 -> 721.5 | I32: 46150 | J32: 46150.167 | K32: =J32-I32 -> 0.16666667 | O32: =N32-M32 -> 0 | R32: =Q32-P32 -> 0 | X32: =W32-V32 -> 0
A33: 46145.292 | B33: 46145.665 | C33: =B33-A33 -> 0.37290509 | E33: 46150.5 | F33: 46151 | G33: =F33-E33 -> 0.49998843 | I33: 46150.292 | K33: =J33-I33 -> -46150.292 | O33: =N33-M33 -> 0 | R33: =Q33-P33 -> 0 | X33: =W33-V33 -> 0
A34: 46146 | B34: 46147 | C34: =B34-A34 -> 0.99998843 | D34: 1397 | E34: 46151 | F34: 46151.417 | G34: =F34-E34 -> 0.41666667 | K34: =J34-I34 -> 0 | O34: =N34-M34 -> 0 | R34: =Q34-P34 -> 0 | X34: =W34-V34 -> 0
A35: 46147 | B35: 46148 | C35: =B35-A35 -> 0.99998837 | D35: 1653 | E35: 46152 | F35: 46152 | G35: =F35-E35 -> 0 | H35: =Sheet1!R41 -> 0 | K35: =J35-I35 -> 0 | O35: =N35-M35 -> 0 | R35: =Q35-P35 -> 0 | X35: =W35-V35 -> 0
A36: 46148 | B36: 46149 | C36: =B36-A36 -> 0.99998837 | D36: 1550 | E36: 46153 | F36: 46153 | G36: =F36-E36 -> 0 | H36: =Sheet1!R42 -> 0 | K36: =J36-I36 -> 0 | O36: =N36-M36 -> 0 | R36: =Q36-P36 -> 0 | X36: =W36-V36 -> 0
A37: 46149 | B37: 46149.167 | C37: =B37-A37 -> 0.16666667 | D37: 1289.4 | E37: 46154 | F37: 46154.562 | G37: =F37-E37 -> 0.5625 | H37: =Sheet1!R43 -> 398.5 | K37: =J37-I37 -> 0 | O37: =N37-M37 -> 0 | R37: =Q37-P37 -> 0 | X37: =W37-V37 -> 0
A38: 46149.333 | C38: =B38-A38 -> -46149.333 | D38: =Sheet1!L40 -> 1203.8 | E38: 46155 | F38: 46155 | G38: =F38-E38 -> 0 | H38: =Sheet1!R44 -> 599.2 | O38: =N38-M38 -> 0 | R38: =Q38-P38 -> 0 | X38: =W38-V38 -> 0
D39: =Sheet1!L41 -> 1279.9 | E39: 46156.458 | F39: 46156.729 | G39: =F39-E39 -> 0.27083333 | H39: =Sheet1!R45 -> 33.6
D40: =Sheet1!L42 -> 664.4 | E40: 46157.688 | F40: 46158 | G40: =F40-E40 -> 0.31248843 | H40: =Sheet1!R46 -> 341.5
...

Sheet Sheet3
B3: Compressor-1 | D3: Compressor-2 | F3: Compressor-3 | H3: Compressor-4 | J3: Compressor-5 | L3: Saving in hrs
A4: Date | B4: Stop time | C4: Start time | D4: Stop time | E4: Start time | F4: Stop time | G4: Start time | H4: Stop time | I4: Start time | J4: Stop time | K4: Start time
A5: 46131 | F5: 0.97916667 | G5: 0.0625 | H5: 0.97916667 | I5: 0.0625 | L5: 4
A6: 46132 | F6: 0.083333333 | G6: 0.16666667 | H6: 0.083333333 | I6: 0.16666667 | J6: 0.083333333 | K6: 0.16666667 | L6: 6
A7: 46133 | D7: 0.00069444444 | E7: 0.1875 | F7: 0.00069444444 | G7: 0.1875 | H7: 0.00069444444 | I7: 0.1875 | L7: 13.5
A8: 46138 | D8: 0.041666667 | E8: 0.20833333 | F8: 0.041666667 | G8: 0.20833333 | H8: 0.041666667 | I8: 0.20833333 | L8: 12
A9: 46139 | B9: 0.020833333 | C9: 0.16666667 | F9: 0.020833333 | G9: 0.16666667 | J9: 0.020833333 | K9: 0.16666667 | L9: 13.5
A10: 46140 | D10: 0.041666667 | E10: 0.20833333 | F10: 0.041666667 | G10: 0.20833333 | H10: 0.041666667 | I10: 0.20833333 | L10: 12
A11: 46141 | B11: 0.083333333 | C11: 0.16666667 | F11: 0.083333333 | G11: 0.16666667 | J11: 0.083333333 | K11: 0.16666667 | L11: 6
A12: 46142 | D12: 12 | E12: 5.2083333 | F12: 12 | G12: 5.2083333 | H12: 12 | I12: 5.2083333 | L12: =3*5 -> 15
A13: 46143 | B13: 12 | C13: 5.2083333 | D13: 12 | E13: 5.2083333 | F13: 12 | G13: 5.2083333 | L13: =3*5 -> 15
A14: 46144 | D14: 12 | E14: 5.2083333 | H14: 12 | I14: 5.2083333 | J14: 12 | K14: 5.2083333 | L14: =3*5 -> 15
A15: 46145
A16: 46146 | B16: 12 | C16: 5.2083333 | F16: 12 | G16: 5.2083333 | J16: 12 | K16: 5.2083333 | L16: =3*5 -> 15
A17: 46147
A18: 46148 | D18: 12 | E18: 5.2083333 | F18: 12 | G18: 5.2083333 | H18: 12 | I18: 5.2083333 | L18: =3*5 -> 15
A19: 46149 | D19: 12 | E19: 5.2083333 | F19: 12 | G19: 5.2083333 | H19: 12 | I19: 5.2083333 | L19: =3*5 -> 15
A20: 46150 | D20: 12 | E20: 5.2083333 | F20: 12 | G20: 5.2083333 | H20: 12 | I20: 5.2083333 | L20: =3*5 -> 15
